js> Object.isExtensible;
function isExtensible() { [native code for Object.isExtensible, arity=1] }
js> Object.isExtensible() === undefined;
true
js> [undefined, null, true, 1, "hello"].forEach(function(val) {
  >   try {
  >     Object.isExtensible(val);
  >     print("Object.isExtensible("+val+") should have thrown a TypeError");
  >   } catch (e if e instanceof TypeError) {
  >     // this was expected
  >   } catch (e) {
  >     print("Object.isExtensible("+val+") should have thrown a TypeError, but instead threw "+e)
  >   }
  > })

js> Object.preventExtensions;
function preventExtensions() { [native code for Object.preventExtensions, arity=1] }
js> Object.preventExtensions() === undefined;
true
js> [undefined, null, true, 1, "hello"].forEach(function(val) {
  >   try {
  >     Object.preventExtensions(val);
  >     print("Object.preventExtensions("+val+") should have thrown a TypeError");
  >   } catch (e if e instanceof TypeError) {
  >     // this was expected
  >   } catch (e) {
  >     print("Object.preventExtensions("+val+") should have thrown a TypeError, but instead threw "+e)
  >   }
  > })

js> var x = {};
js> Object.isExtensible(x);
true
js> var y = Object.preventExtensions(x);
js> y === x;
true
js> Object.isExtensible(x);
false

js> try { 
  >   x.a = 1; 
  >   print("'x.a = 1' should have thrown a TypeError as x is not extensible"); 
  > } catch (e if e instanceof TypeError) {
  >   // this was expected
  > } catch (e) {
  >   print("'x.a = 1' should have thrown a TypeError, but instead threw "+e)
  > }
js> try { 
  >   x.__defineGetter__('a', function() { return 1 })
  >   print("'x.__defineGetter__('a', function() { return 1 })' should have thrown a TypeError as x is not extensible"); 
  > } catch (e if e instanceof TypeError) {
  >   // this was expected
  > } catch (e) {
  >   print("'x.__defineGetter__('a', function() { return 1 })' should have thrown a TypeError, but instead threw "+e)
  > }
js>
